ERROR:root:Internal Python error in the inspect module.
Below is the traceback from this internal error.

❌ Registration failed: 400 Client Error: Bad Request for url: https://ff2e6297-cbf6-4c2e-ac26-3872e4c9c3ae-00-1vce3mtitdkqj.janeway.replit.dev/api/gpu/workers/register
⚠️  Make sure AION_URL is correct and AION is running!
Traceback (most recent call last):
  File "/tmp/ipython-input-3073142729.py", line 25, in <cell line: 0>
    response.raise_for_status()
  File "/usr/local/lib/python3.12/dist-packages/requests/models.py", line 1026, in raise_for_status
    raise HTTPError(http_error_msg, response=self)
requests.exceptions.HTTPError: 400 Client Error: Bad Request for url: https://ff2e6297-cbf6-4c2e-ac26-3872e4c9c3ae-00-1vce3mtitdkqj.janeway.replit.dev/api/gpu/workers/register

During handling of the above exception, another exception occurred:

Traceback (most recent call last):
  File "/usr/local/lib/python3.12/dist-packages/IPython/core/interactiveshell.py", line 3553, in run_code
    exec(code_obj, self.user_global_ns, self.user_ns)
  File "/tmp/ipython-input-3073142729.py", line 32, in <cell line: 0>
    sys.exit(1)
SystemExit: 1

During handling of the above exception, another exception occurred:

Traceback (most recent call last):
  File "/usr/local/lib/python3.12/dist-packages/IPython/core/ultratb.py", line 1101, in get_records
    return _fixed_getinnerframes(etb, number_of_lines_of_context, tb_offset)
           ^^^^^^^^^^^^^^^^^^^^^^^^^^^^^^^^^^^^^^^^^^^^^^^^^^^^^^^^^^^^^^^^^
  File "/usr/local/lib/python3.12/dist-packages/IPython/core/ultratb.py", line 248, in wrapped
    return f(*args, **kwargs)
           ^^^^^^^^^^^^^^^^^^
  File "/usr/local/lib/python3.12/dist-packages/IPython/core/ultratb.py", line 281, in _fixed_getinnerframes
    records = fix_frame_records_filenames(inspect.getinnerframes(etb, context))
                                          ^^^^^^^^^^^^^^^^^^^^^^^^^^^^^^^^^^^^
  File "/usr/lib/python3.12/inspect.py", line 1769, in getinnerframes
    traceback_info = getframeinfo(tb, context)
                     ^^^^^^^^^^^^^^^^^^^^^^^^^
  File "/usr/lib/python3.12/inspect.py", line 1701, in getframeinfo
    lineno = frame.f_lineno
             ^^^^^^^^^^^^^^
AttributeError: 'tuple' object has no attribute 'f_lineno'
---------------------------------------------------------------------------
HTTPError                                 Traceback (most recent call last)
/tmp/ipython-input-3073142729.py in <cell line: 0>()
     24     )
---> 25     response.raise_for_status()
     26     worker_data = response.json()

9 frames
HTTPError: 400 Client Error: Bad Request for url: https://ff2e6297-cbf6-4c2e-ac26-3872e4c9c3ae-00-1vce3mtitdkqj.janeway.replit.dev/api/gpu/workers/register

During handling of the above exception, another exception occurred:

SystemExit                                Traceback (most recent call last)
    [... skipping hidden 1 frame]

SystemExit: 1

During handling of the above exception, another exception occurred:

TypeError                                 Traceback (most recent call last)
    [... skipping hidden 1 frame]

/usr/local/lib/python3.12/dist-packages/IPython/core/ultratb.py in find_recursion(etype, value, records)
    380     # first frame (from in to out) that looks different.
    381     if not is_recursion_error(etype, value, records):
--> 382         return len(records), 0
    383 
    384     # Select filename, lineno, func_name to track frames with

TypeError: object of type 'NoneType' has no len()
